Workbook

Sheet 原始数据
A1: 数据库：年度数据
A2: 时间：
A3: 指标 | B3: 2022年 | C3: 2021年 | D3: 2020年 | E3: 2019年 | F3: 2018年 | G3: 2017年 | H3: 2016年
A4: 能源消费总量 (万吨标准煤) 去除 | B4: 541274 | C4: 525027 | D4: 496514 | E4: 485584 | F4: 471925 | G4: 455827 | H4: 441492
A5: 农、林、牧、渔业能源消费总量(万吨标准煤) | B5: 10090 | C5: 9661 | D5: 9263 | E5: 9018 | F5: 8781 | G5: 8945 | H5: 8585
A6: 工业能源消费总量 (万吨标准煤) 去除 | B6: 363782 | C6: 348551 | D6: 332625 | E6: 322503 | F6: 311151 | G6: 302308 | H6: 295615
A7: 采矿业能源消费总量 (万吨标准煤)去除 | B7: 18258 | C7: 18298 | D7: 17451 | E7: 19233 | F7: 18981 | G7: 18099 | H7: 17773
A8: 煤炭开采和洗选业能源消费总量(万吨标准煤) | B8: 8811 | C8: 9035 | D8: 8953 | E8: 10133 | F8: 9983 | G8: 9646 | H8: 9436
A9: 石油和天然气开采业能源消费总量 (万吨标准煤) | B9: 4461 | C9: 4155 | D9: 3743 | E9: 3755 | F9: 3818 | G9: 3956 | H9: 3916
A10: 黑色金属矿采选业能源消费总量 (万吨标准煤) | B10: 1757 | C10: 1897 | D10: 1728 | E10: 1660 | F10: 1566 | G10: 1537 | H10: 1458
A11: 有色金属矿采选业能源消费总量 (万吨标准煤) | B11: 1114 | C11: 1082 | D11: 1090 | E11: 1258 | F11: 1253 | G11: 1106 | H11: 1076
A12: 金属矿采选产品 | B12: =SUM(B10:B11) -> 2871
A13: 非金属矿采选业能源消费总量 (万吨标准煤) | B13: 1209 | C13: 1273 | D13: 1126 | E13: 1324 | F13: 1312 | G13: 1185 | H13: 1260
A14: 开采专业及辅助性活动能源消费总量 (万吨标准煤) | B14: 406 | C14: 341 | D14: 322 | E14: 470 | F14: 464 | G14: 321 | H14: 286
A15: 其他采矿业能源消费总量 (万吨标准煤) | B15: 499 | C15: 516 | D15: 488 | E15: 633 | F15: 584 | G15: 347 | H15: 341
A16: 非金属矿和其他矿采选产品 | B16: =SUM(B13:B15) -> 2114
A17: 制造业能源消费总量 (万吨标准煤)去除 | B17: 307086 | C17: 293065 | D17: 279651 | E17: 268426 | F17: 258604 | G17: 252462 | H17: 247658
A18: 农副食品加工业能源消费总量 (万吨标准煤) | B18: 4296 | C18: 4315 | D18: 4002 | E18: 4126 | F18: 4036 | G18: 4145 | H18: 4241
A19: 食品制造业能源消费总量 (万吨标准煤) | B19: 2769 | C19: 2417 | D19: 2148 | E19: 2042 | F19: 1959 | G19: 1965 | H19: 1976
A20: 酒、饮料和精制茶制造业能源消费总量 (万吨标准煤) | B20: 1339 | C20: 1287 | D20: 1199 | E20: 1283 | F20: 1317 | G20: 1403 | H20: 1496
A21: 烟草制品业能源消费总量 (万吨标准煤) | B21: 192 | C21: 186 | D21: 180 | E21: 192 | F21: 198 | G21: 200 | H21: 206
A22: 食品和烟草 | B22: =SUM(B18:B21) -> 8596
A23: 纺织业能源消费总量 (万吨标准煤) | B23: 7268 | C23: 7932 | D23: 6982 | E23: 7398 | F23: 7372 | G23: 7518 | H23: 7303
A24: 纺织服装、服饰业能源消费总量 (万吨标准煤) | B24: 912 | C24: 989 | D24: 854 | E24: 905 | F24: 866 | G24: 882 | H24: 946
A25: 皮革、毛皮、羽毛及其制品和制鞋业能源消费总量 (万吨标准煤) | B25: 531 | C25: 535 | D25: 489 | E25: 539 | F25: 546 | G25: 563 | H25: 607
A26: 纺织服装鞋帽皮革羽绒及其制品 | B26: =SUM(B24:B25) -> 1443
A27: 木材加工及木、竹、藤、棕、草制品业能源消费总量 (万吨标准煤) | B27: 1094 | C27: 1154 | D27: 1007 | E27: 1036 | F27: 1059 | G27: 1082 | H27: 1194
A28: 家具制造业能源消费总量 (万吨标准煤) | B28: 439 | C28: 459 | D28: 393 | E28: 383 | F28: 367 | G28: 353 | H28: 364
A29: 木材加工品和家具 | B29: =SUM(B27:B28) -> 1533
A30: 造纸及纸制品业能源消费总量 (万吨标准煤) | B30: 4462 | C30: 4204 | D30: 3927 | E30: 3847 | F30: 4102 | G30: 4314 | H30: 4115
A31: 印刷和记录媒介复制业能源消费总量 (万吨标准煤) | B31: 550 | C31: 556 | D31: 498 | E31: 508 | F31: 517 | G31: 484 | H31: 481
A32: 文教、工美、体育和娱乐用品制造业能源消费总量 (万吨标准煤) | B32: 460 | C32: 545 | D32: 501 | E32: 493 | F32: 461 | G32: 435 | H32: 410
A33: 造纸印刷和文教体育用品 | B33: =SUM(B30:B32) -> 5472
A34: 石油、煤炭及其他燃料加工业能源消费总量(万吨标准煤) | B34: 41969 | C34: 36720 | D34: 35267 | E34: 32572 | F34: 28689 | G34: 26458 | H34: 24165
A35: 化学原料及化学制品制造业能源消费总量 (万吨标准煤) | B35: 66327 | C35: 60405 | D35: 56723 | E35: 53272 | F35: 51278 | G35: 49356 | H35: 49722
A36: 医药制造业能源消费总量 (万吨标准煤) | B36: 2603 | C36: 2395 | D36: 2259 | E36: 2179 | F36: 2179 | G36: 2251 | H36: 2323
A37: 化学纤维制造业能源消费总量 (万吨标准煤) | B37: 2634 | C37: 2713 | D37: 2355 | E37: 2416 | F37: 2329 | G37: 2204 | H37: 2075
A38: 橡胶和塑料制品业能源消费总量 (万吨标准煤) | B38: 5380 | C38: 5547 | D38: 4990 | E38: 4868 | F38: 4793 | G38: 4771 | H38: 4538
A39: 化学产品 | B39: =SUM(B35:B38) -> 76944
A40: 非金属矿物制品 | B40: 37049 | C40: 36039 | D40: 35387 | E40: 33344 | F40: 32798 | G40: 33343 | H40: 34772
...

Sheet 2022年度数据
A1: 指标 | B1: 2022年
A2: 农、林、牧、渔业能源消费总量(万吨标准煤) | B2: 10090
A3: 煤炭开采和洗选业能源消费总量(万吨标准煤) | B3: 8811
A4: 石油和天然气开采业能源消费总量 (万吨标准煤) | B4: 4461
A5: 金属矿采选产品 | B5: 2871
A6: 非金属矿和其他矿采选产品 | B6: 2114
A7: 食品和烟草 | B7: 8596
A8: 纺织业能源消费总量 (万吨标准煤) | B8: 7268
A9: 纺织服装鞋帽皮革羽绒及其制品 | B9: 1443
A10: 木材加工品和家具 | B10: 1533
A11: 造纸印刷和文教体育用品 | B11: 5472
A12: 石油、煤炭及其他燃料加工业能源消费总量(万吨标准煤) | B12: 41969
A13: 化学产品 | B13: 76944
... A31: 其他能源消费总量(万吨标准煤) | B31: 32375

Sheet 42部门能源消费数据
A1: 指标 | B1: 2022年
A2: 农、林、牧、渔业能源消费总量(万吨标准煤) | B2: 10090 | C2: 农、林、牧、渔业能源消费总量(万吨标准煤)
A3: 煤炭开采和洗选业能源消费总量(万吨标准煤) | B3: 8811 | C3: 煤炭开采和洗选业能源消费总量(万吨标准煤)
A4: 石油和天然气开采业能源消费总量 (万吨标准煤) | B4: 4461 | C4: 石油和天然气开采业能源消费总量(万吨标准煤)
A5: 金属矿采选产品 | B5: 2871 | C5: 金属矿采选产品
A6: 非金属矿和其他矿采选产品 | B6: 2114 | C6: 非金属矿和其他矿采选产品
A7: 食品和烟草 | B7: 8596 | C7: 食品和烟草
A8: 纺织业能源消费总量 (万吨标准煤) | B8: 7268 | C8: 纺织业能源消费总量(万吨标准煤)
A9: 纺织服装鞋帽皮革羽绒及其制品 | B9: 1443 | C9: 纺织服装鞋帽皮革羽绒及其制品
A10: 木材加工品和家具 | B10: 1533 | C10: 木材加工品和家具
A11: 造纸印刷和文教体育用品 | B11: 5472 | C11: 造纸印刷和文教体育用品
A12: 石油、煤炭及其他燃料加工业能源消费总量(万吨标准煤) | B12: 41969 | C12: 石油、煤炭及其他燃料加工业能源消费总量(万吨标准煤)
A13: 化学产品 | B13: 76944 | C13: 化学产品
... A28: 建筑业能源消费总量(万吨标准煤) | B28: 8371 | C28: 建筑业能源消费总量(万吨标准煤)
B29: ='2020居民消费支出'!D28*'2022年度数据'!B30 -> 6873.1235 | C29: 批发和零售
B30: 40434 | C30: 交通运输、仓储和邮政业能源消费总量(万吨标准煤)
B31: ='2020居民消费支出'!D30*'2022年度数据'!B30 -> 8468.8765 | C31: 住宿和餐饮
B32: ='2020居民消费支出'!F$31*'2022年度数据'!$B31 -> 3136.7205 | C32: 信息传输、软件和信息技术服务
B33: ='2020居民消费支出'!F32*'2022年度数据'!B31 -> 6215.9557 | C33: 金融
B34: ='2020居民消费支出'!F33*'2022年度数据'!B31 -> 10293.739 | C34: 房地产
B35: ='2020居民消费支出'!F34*'2022年度数据'!B31 -> 812.77827 | C35: 租赁和商务服务
B36: ='2020居民消费支出'!F35*'2022年度数据'!B31 -> 0 | C36: 研究和试验发展
B37: ='2020居民消费支出'!F36*'2022年度数据'!B31 -> 64.621945 | C37: 综合技术服务
B38: ='2020居民消费支出'!F37*'2022年度数据'!B31 -> 94.838208 | C38: 水利、环境和公共设施管理
B39: ='2020居民消费支出'!F38*'2022年度数据'!B31 -> 2982.439 | C39: 居民服务、修理和其他服务
B40: ='2020居民消费支出'!F39*'2022年度数据'!B31 -> 3974.607 | C40: 教育
B41: ='2020居民消费支出'!F40*'2022年度数据'!B31 -> 3058.0428 | C41: 卫生和社会工作
B42: ='2020居民消费支出'!F41*'2022年度数据'!B31 -> 1668.9229 | C42: 文化、体育和娱乐
B43: ='2020居民消费支出'!F42*'2022年度数据'!B31 -> 72.335127 | C43: 公共管理、社会保障和社会组织

Sheet 2022E
A1: 指标 | B1: 部门 | C1: 2022年能源消费量（万吨标准煤） | D1: 2022年总产出（万元） | E1: E（单位产出能源消耗强度）（吨标准煤/万元）
A2: 农林牧渔产品及服务 | B2: 农林牧渔产品和服务 | C2: 10090 | D2: 1.5978103e+09 | E2: =C2/D2*10000 -> 0.063148922
A3: 煤炭开采和洗选产品 | B3: 煤炭采选产品 | C3: 8811 | D3: 3.7055969e+08 | E3: =C3/D3*10000 -> 0.23777546
A4: 石油和天然气开采产品 | B4: 石油和天然气开采产品 | C4: 4461 | D4: 1.6465292e+08 | E4: =C4/D4*10000 -> 0.27093355
A5: 金属矿采选产品 | B5: 金属矿采选产品 | C5: 2871 | D5: 1.2029961e+08 | E5: =C5/D5*10000 -> 0.23865414
A6: 非金属矿和其他矿采选产品 | B6: 非金属矿和其他矿采选产品 | C6: 2114 | D6: 84842777 | E6: =C6/D6*10000 -> 0.24916676
A7: 食品和烟草 | B7: 食品和烟草 | C7: 8596 | D7: 1.1471153e+09 | E7: =C7/D7*10000 -> 0.074935796
A8: 纺织品 | B8: 纺织品 | C8: 7268 | D8: 3.062868e+08 | E8: =C8/D8*10000 -> 0.23729394
A9: 纺织服装鞋帽皮革羽绒及其制品 | B9: 纺织服装鞋帽皮革羽绒及其制品 | C9: 1443 | D9: 3.3563064e+08 | E9: =C9/D9*10000 -> 0.042993691
A10: 木材加工品和家具 | B10: 木材加工品和家具 | C10: 1533 | D10: 2.9146927e+08 | E10: =C10/D10*10000 -> 0.052595596
A11: 造纸印刷和文教体育用品 | B11: 造纸印刷和文教体育用品 | C11: 5472 | D11: 4.5379095e+08 | E11: =C11/D11*10000 -> 0.12058416
A12: 石油、炼焦产品和核燃料加工品 | B12: 石油、炼焦产品和核燃料加工品（一部分给交通通信、一部分作为燃料给居住） | C12: 41969 | D12: 5.6436576e+08 | E12: =C12/D12*10000 -> 0.74364893
A13: 化学产品 | B13: 化学产品（一部分给家庭设备用品，一部分给医疗保健） | C13: 76944 | D13: 1.7901232e+09 | E13: =C13/D13*10000 -> 0.42982516
... A43: 公共管理、社会保障和社会组织 | B43: 公共管理、社会保障和社会组织 | C43: 72.335127 | D43: 1.0007928e+09 | E43: =C43/D43*10000 -> 0.00072277824

Sheet 2020居民消费支出
A1: 农林牧渔产品及服务 | B1: 5.0581814e+08
A2: 煤炭开采和洗选产品 | B2: 474648.35
A3: 石油和天然气开采产品 | B3: 0
A4: 金属矿采选产品 | B4: 0
A5: 非金属矿和其他矿采选产品 | B5: 0
A6: 食品和烟草 | B6: 4.8529237e+08
A7: 纺织品 | B7: 13745625
A8: 纺织服装鞋帽皮革羽绒及其制品 | B8: 1.4898727e+08
A9: 木材加工品和家具 | B9: 22882952
A10: 造纸印刷和文教体育用品 | B10: 52017008
A11: 石油、炼焦产品和核燃料加工品 | B11: 39344775
A12: 化学产品 | B12: 1.5245505e+08
... A25: 燃气生产和供应 | B25: 38556163
A26: 水的生产和供应 | B26: 19525092 | D26: 批发、零售、住宿、餐饮 | F26: 其他
A27: 建筑 | B27: 0 | D27: =B28+B30 -> 6.7998792e+08 | F27: =SUM(B31:B42) -> 2.2856777e+09
A28: 批发和零售 | B28: 3.0463049e+08 | D28: =B28/D27 -> 0.44799397
A29: 交通运输、仓储和邮政 | B29: 1.3993299e+08
A30: 住宿和餐饮 | B30: 3.7535743e+08 | D30: =B30/D27 -> 0.55200603
A31: 信息传输、软件和信息技术服务 | B31: 2.2145273e+08 | F31: =B31/F$27 -> 0.096887118
A32: 金融 | B32: 4.38847e+08 | F32: =B32/F$27 -> 0.19199863
A33: 房地产 | B33: 7.2673882e+08 | F33: =B33/F$27 -> 0.31795332
A34: 租赁和商务服务 | B34: 57382214 | F34: =B34/F$27 -> 0.02510512
A35: 研究和试验发展 | B35: 0 | F35: =B35/F$27 -> 0
A36: 综合技术服务 | B36: 4562314.8 | F36: =B36/F$27 -> 0.0019960446
A37: 水利、环境和公共设施管理 | B37: 6695585.5 | F37: =B37/F$27 -> 0.0029293655
A38: 居民服务、修理和其他服务 | B38: 2.1056044e+08 | F38: =B38/F$27 -> 0.092121667
A39: 教育 | B39: 2.8060759e+08 | F39: =B39/F$27 -> 0.12276778
A40: 卫生和社会工作 | B40: 2.1589808e+08 | F40: =B40/F$27 -> 0.09445692
A41: 文化、体育和娱乐 | B41: 1.178261e+08 | F41: =B41/F$27 -> 0.051549742
A42: 公共管理、社会保障和社会组织 | B42: 5106866 | F42: =B42/F$27 -> 0.0022342896
